Workbook

Sheet 1. Kapak
A1: VALİDASYON HESAPLAMA DOĞRULAMA RAPORU
A3: Validasyon Kodu | B3: K.SOP.05-Ek.1
A4: Validasyon Başlığı | B4: DMFu Tayini Validasyonu
A5: Metot | B5: DMFu Tayini
A6: Metot Kodu | B6: K.SOP.05
A7: Teknik | B7: ISO 16186:2021
A8: Matriks (metot) | B8: Ayakkabı
A9: Çalışma Tipi | B9: VERIFICATION
A10: Durum | B10: COMPLETED
A11: Komponentler | B11: Fumaric acid, bis-mehyl ester (DMFu); Maleic acid, bis-methyl ester (DMMa)
A12: Personel | B12: Ali Berkan Akdoğan; Efsu Nur Akyol
A13: Aktif Validasyon Parametreleri | B13: Doğrusallık (Linearity), LOD (Tespit Limiti) ve LOQ (Tayini Limiti), Kesinlik (Tekrarlanabilirlik), Gerçeklik (Bias / Geri Kazanım), Kesinlik (Tekrarüretilebilirlik)
A14: Doküman Üretim Tarihi | B14: 2026-05-31
A16: AMAÇ
A17: Bu dosya, ÜGD Portal Eurolab Validasyon ekranındaki (Validasyon ID = 21) tüm
A18: istatistiksel hesaplamaların doğruluğunu denetim/akreditasyon süreçlerine kanıt
A19: olarak sunmak amacıyla, kaynak kod algoritmaları baz alınarak hazırlanmıştır.
A21: HER SAYFADA:
A22: 1) Bölümün TEORİK FORMÜLÜ (matematik notasyonu)
A23: 2) Validasyon 21'in GİRİŞ VERİLERİ (sistemde girilmiş ham veriler)
A24: 3) Excel HÜCRE FORMÜLÜ ile adım adım hesap (denetçi hücreye tıklayarak doğrulayabilir)
A25: 4) Sistemin verdiği SONUÇ ile karşılaştırma (Fark sütunu ≈ 0 olmalı)
A27: REFERANSLAR
A28: • ISO 5725-2: Tekrarlanabilirlik ve Tekrarüretilebilirlik (r = 2.83·Sr)
A29: • ISO/IEC Guide 98-3 (GUM): Belirsizlik bütçesi (k=2, %95)
... A34: İÇİNDEKİLER
A35: Sayfa 2 | B35: LOD ve LOQ — Tespit / Tayin Limiti
A36: Sayfa 3 | B36: Doğrusallık (Linearity) — En Küçük Kareler Regresyonu
A37: Sayfa 4 | B37: Tekrarlanabilirlik — Sr, RSDr, r, Havuzlanmış RSD + Grubbs
A38: Sayfa 5 | B38: Tekrarüretilebilirlik — Pooled RSD + F-testi + Grubbs
A39: Sayfa 6 | B39: Gerçeklik (Trueness) — Recovery%, Bias, U(Bias), t-testi + Grubbs
A40: Sayfa 7 | B40: Ölçüm Belirsizliği (GUM) — Birleşik (uc) ve Genişletilmiş (U)
A41: Sayfa 8 | B41: Grubbs Kritik Değer Tablosu (α=0.05, n=3-30)
A42: Sayfa 9 | B42: Eurachem Rehber Uygunluk Değerlendirmesi

Sheet 2. LOD-LOQ
A1: LOD / LOQ — TESPİT VE TAYİN LİMİTİ HESAPLAMASI
A3: TEORİK FORMÜL (Kaynak: components/validation/modules/LodCalculationForm.tsx, satır 90-119)
A4: Ortalama μ = Σx / n (n = toplam ölçüm sayısı)
A5: Standart Sapma σ = √[ Σ(xi − μ)² / (n − 1) ] (Bessel düzeltmesi)
A6: LOD (Tespit Limiti) = μ + 3·σ
A7: LOQ (Tayin Limiti) = μ + 10·σ
A8: NOT: 2 personel × 10 tekrar = toplam 20 ölçüm. Tüm değerler tek havuzda birleştirilir.
A10: KOMPONENT: Fumaric acid, bis-mehyl ester (DMFu) | Birim: mg_L
A11: Notlar: Tayin ve Tespit Limiti çalışmaları için 2 personel tarafından lineerite aralığının en düşük noktasında 10'ar adet spike test numunesi çalışılmıştır. Elde edilen ölçüm değerlerinin ortalamaları ve standart sapmaları hesaplanmış, ortalamaya standart sa
A13: No | B13: Ali Berkan Akdoğan | C13: Efsu Nur Akyol
A14: 1 | B14: 0.1 | C14: 0.1
A15: 2 | B15: 0.08 | C15: 0.1
A16: 3 | B16: 0.09 | C16: 0.1
A17: 4 | B17: 0.09 | C17: 0.09
A18: 5 | B18: 0.09 | C18: 0.1
A19: 6 | B19: 0.09 | C19: 0.11
A20: 7 | B20: 0.09 | C20: 0.09
A21: 8 | B21: 0.1 | C21: 0.12
A22: 9 | B22: 0.09 | C22: 0.09
A23: 10 | B23: 0.09 | C23: 0.1
A25: Hesap | B25: Excel Formülü (denetçi: hücreye tıklayın) | C25: Hesap Sonucu | D25: Sistem Sonucu | E25: Fark
A26: n (toplam ölçüm) | B26: =COUNT(B14:C23) | C26: =COUNT(B14:C23) | D26: 20 | E26: =C26-D26
A27: Ortalama μ = AVERAGE(...) | B27: =AVERAGE(B14:C23) | C27: =AVERAGE(B14:C23) | D27: 0.0955 | E27: =C27-D27
A28: Standart Sapma σ = STDEV(...) | B28: =STDEV(B14:C23) | C28: =STDEV(B14:C23) | D28: 0.0088704121 | E28: =C28-D28
A29: LOD = μ + 3·σ | B29: =AVERAGE(B14:C23)+3*STDEV(B14:C23) | C29: =AVERAGE(B14:C23)+3*STDEV(B14:C23) | D29: 0.12211124 | E29: =C29-D29
A30: LOQ = μ + 10·σ | B30: =AVERAGE(B14:C23)+10*STDEV(B14:C23) | C30: =AVERAGE(B14:C23)+10*STDEV(B14:C23) | D30: 0.18420412 | E30: =C30-D30
A33: KOMPONENT: Maleic acid, bis-methyl ester (DMMa) | Birim: mg_L
A34: Notlar: Tayin ve Tespit Limiti çalışmaları için 2 personel tarafından lineerite aralığının en düşük noktasında 10'ar adet spike test numunesi çalışılmıştır. Elde edilen ölçüm değerlerinin ortalamaları ve standart sapmaları hesaplanmış, ortalamaya standart sa
A36: No | B36: Ali Berkan Akdoğan | C36: Efsu Nur Akyol
A37: 1 | B37: 0.11 | C37: 0.1051
A38: 2 | B38: 0.1 | C38: 0.10531
A39: 3 | B39: 0.1 | C39: 0.10201
A40: 4 | B40: 0.1 | C40: 0.10257
A41: 5 | B41: 0.1 | C41: 0.11108
A42: 6 | B42: 0.1 | C42: 0.11451
A43: 7 | B43: 0.1 | C43: 0.10985
A44: 8 | B44: 0.11 | C44: 0.10988
A45: 9 | B45: 0.1 | C45: 0.09689
A46: 10 | B46: 0.1 | C46: 0.11263
A48: Hesap | B48: Excel Formülü (denetçi: hücreye tıklayın) | C48: Hesap Sonucu | D48: Sistem Sonucu | E48: Fark
...

Sheet 3. Doğrusallık
A1: DOĞRUSALLIK (LINEARITY) — EN KÜÇÜK KARELER REGRESYONU
A3: TEORİK FORMÜLLER (Kaynak: LinearityCalculationForm.tsx)
A4: Eğim b1 = (n·ΣXY − ΣX·ΣY) / (n·ΣX² − (ΣX)²) (Excel: =SLOPE(Y;X))
A5: Kesim a = (ΣY − b1·ΣX) / n (Excel: =INTERCEPT(Y;X))
A6: Korelasyon r = (n·ΣXY − ΣX·ΣY) / √[(n·ΣX²−(ΣX)²)(n·ΣY²−(ΣY)²)] (Excel: =PEARSON(X;Y))
A7: R² = r² (Excel: =RSQ(Y;X))
A8: Tahmin ŷ = b1·x + a
A9: Hata sapma s = √[ Σ(y − ŷ)² / (n − 2) ] (Excel: =STEYX(Y;X))
A10: U(Co) = (s/b1)·√(1/p + 1/(n·p) + (Co − x̄)²/Sxx) (p=3, lab konvansiyonu)
A11: Sxx = Σ(xi − x̄)² (türetilmiş xi üzerinden)
A13: KOMPONENT: Fumaric acid, bis-mehyl ester (DMFu) | Birim: mg_L | Çalışma aralığı: 0.01 - 0.25 mg/L
A15: Seviye | B15: X (Konsantrasyon) | C15: Y (Cevap) | D15: ŷ Tahmin | E15: Residual (Y−ŷ) | F15: (Y−ŷ)²
A16: L1 | B16: 0.01 | C16: 773 | D16: =SLOPE(C16:C21,B16:B21)*B16+INTERCEPT(C16:C21,B16:B21) | E16: =C16-D16 | F16: =(C16-D16)^2
A17: L2 | B17: 0.05 | C17: 4756 | D17: =SLOPE(C16:C21,B16:B21)*B17+INTERCEPT(C16:C21,B16:B21) | E17: =C17-D17 | F17: =(C17-D17)^2
A18: L3 | B18: 0.1 | C18: 11750.67 | D18: =SLOPE(C16:C21,B16:B21)*B18+INTERCEPT(C16:C21,B16:B21) | E18: =C18-D18 | F18: =(C18-D18)^2
A19: L4 | B19: 0.15 | C19: 20449 | D19: =SLOPE(C16:C21,B16:B21)*B19+INTERCEPT(C16:C21,B16:B21) | E19: =C19-D19 | F19: =(C19-D19)^2
A20: L5 | B20: 0.2 | C20: 25948.33 | D20: =SLOPE(C16:C21,B16:B21)*B20+INTERCEPT(C16:C21,B16:B21) | E20: =C20-D20 | F20: =(C20-D20)^2
A21: L6 | B21: 0.25 | C21: 31267 | D21: =SLOPE(C16:C21,B16:B21)*B21+INTERCEPT(C16:C21,B16:B21) | E21: =C21-D21 | F21: =(C21-D21)^2
A23: Hesap | B23: Excel Formülü | C23: Hesap Sonucu | D23: Sistem Sonucu | E23: Fark
A24: n (nokta sayısı) | B24: =COUNT(B16:B21) | C24: =COUNT(B16:B21) | D24: 6 | E24: =C24-D24
A25: Slope b1 = SLOPE(Y;X) | B25: =SLOPE(C16:C21,B16:B21) | C25: =SLOPE(C16:C21,B16:B21) | D25: 132293.3 | E25: =C25-D25
A26: Intercept a = INTERCEPT(Y;X) | B26: =INTERCEPT(C16:C21,B16:B21) | C26: =INTERCEPT(C16:C21,B16:B21) | D26: -933.15113 | E26: =C26-D26
A27: Korelasyon r = PEARSON(X;Y) | B27: =PEARSON(B16:B21,C16:C21) | C27: =PEARSON(B16:B21,C16:C21) | D27: 0.99683006 | E27: =C27-D27
A28: R² = RSQ(Y;X) | B28: =RSQ(C16:C21,B16:B21) | C28: =RSQ(C16:C21,B16:B21) | D28: 0.99367016 | E28: =C28-D28
A29: Hata Std s = STEYX(Y;X) | B29: =STEYX(C16:C21,B16:B21) | C29: =STEYX(C16:C21,B16:B21)
A30: Co = MAX(X) | B30: =MAX(B16:B21) | C30: =MAX(B16:B21) | D30: 0.25 | E30: =C30-D30
A31: Cort (x̄) = AVERAGE(X) | B31: =AVERAGE(B16:B21) | C31: =AVERAGE(B16:B21) | D31: 0.12666667 | E31: =C31-D31
A32: Σ(Y−ŷ)² (Residual Sum of Squares) | B32: =SUM(F16:F21) | C32: =SUM(F16:F21)
A33: Denklem | C33: y = 132293.2984x - 933.1511 | D33: y = 132293.2984x - 933.1511
A34: U(Co) — sistem hesabı | C34: 0.0070476629 | D34: 0.0070476629
A35: Sxx — sistem hesabı | C35: 0.041596633 | D35: 0.041596633
A38: KOMPONENT: Maleic acid, bis-methyl ester (DMMa) | Birim: mg_L | Çalışma aralığı: 0.01 - 0.25 mg/L
A40: Seviye | B40: X (Konsantrasyon) | C40: Y (Cevap) | D40: ŷ Tahmin | E40: Residual (Y−ŷ) | F40: (Y−ŷ)²
A41: L1 | B41: 0.01 | C41: 1559.67 | D41: =SLOPE(C41:C46,B41:B46)*B41+INTERCEPT(C41:C46,B41:B46) | E41: =C41-D41 | F41: =(C41-D41)^2
A42: L2 | B42: 0.05 | C42: 7789 | D42: =SLOPE(C41:C46,B41:B46)*B42+INTERCEPT(C41:C46,B41:B46) | E42: =C42-D42 | F42: =(C42-D42)^2
A43: L3 | B43: 0.1 | C43: 18512.67 | D43: =SLOPE(C41:C46,B41:B46)*B43+INTERCEPT(C41:C46,B41:B46) | E43: =C43-D43 | F43: =(C43-D43)^2
A44: L4 | B44: 0.15 | C44: 31433.33 | D44: =SLOPE(C41:C46,B41:B46)*B44+INTERCEPT(C41:C46,B41:B46) | E44: =C44-D44 | F44: =(C44-D44)^2
A45: L5 | B45: 0.2 | C45: 39735.33 | D45: =SLOPE(C41:C46,B41:B46)*B45+INTERCEPT(C41:C46,B41:B46) | E45: =C45-D45 | F45: =(C45-D45)^2
A46: L6 | B46: 0.25 | C46: 46885 | D46: =SLOPE(C41:C46,B41:B46)*B46+INTERCEPT(C41:C46,B41:B46) | E46: =C46-D46 | F46: =(C46-D46)^2
A48: Hesap | B48: Excel Formülü | C48: Hesap Sonucu | D48: Sistem Sonucu | E48: Fark
...

Sheet 4. Tekrarlanabilirlik
A1: TEKRARLANABİLİRLİK (REPEATABILITY) — Sr, RSDr, r, HAVUZLANMIŞ RSD
A3: TEORİK FORMÜLLER (Kaynak: PrecisionRepeatabilityForm.tsx)
A4: Personel başına:
A5: x̄ = Σx / n
A6: Sr = √[ Σ(xi − x̄)² / (n−1) ]
A7: RSDr = Sr / x̄
A8: r (tekrarlanabilirlik limiti) = 2.83 · Sr (ISO 5725, ≈ 2√2)
A9: Pool katkısı = RSDr² · (n − 1)
A10: Havuzlanmış RSD (her düzey için):
A11: RSDpool = √[ Σ(RSDr² · (n−1)) / Σ(n−1) ]
A12: Uygunluk: |paralel1 − paralel2| < r ise UYGUN.
A14: KOMPONENT: Fumaric acid, bis-mehyl ester (DMFu) | Birim: mg_kg
A16: DÜZEY: Düşük Seviye | Matriks: Tekstil | Hedef: 0,5
A17: No | B17: Ali Berkan Akdoğan - Par.1 | C17: Ali Berkan Akdoğan - Par.2 | D17: Efsu Nur Akyol - Par.1 | E17: Efsu Nur Akyol - Par.2
A18: 1 | B18: 0.504 | C18: 0.508 | D18: 0.517 | E18: 0.505
A19: 2 | B19: 0.46 | C19: 0.498 | D19: 0.509 | E19: 0.525
A20: 3 | B20: 0.46 | C20: 0.472 | D20: 0.486 | E20: 0.514
A21: 4 | B21: 0.489 | C21: 0.472 | D21: 0.551 | E21: 0.54
A22: 5 | B22: 0.452 | C22: 0.487 | D22: 0.537 | E22: 0.517
A23: 6 | B23: 0.457 | C23: 0.49 | D23: 0.542 | E23: 0.528
A25: Hesap | B25: Excel Formülü | C25: Hesap | D25: Sistem | E25: Fark
A26: ── Ali Berkan Akdoğan ──
A27: n | B27: =COUNT(B18:C23) | C27: =COUNT(B18:C23) -> 12 | D27: 12 | E27: =C27-D27 -> 0
A28: x̄ = AVERAGE(...) | B28: =AVERAGE(B18:C23) | C28: =AVERAGE(B18:C23) -> 0.47908333 | D28: 0.47908333 | E28: =C28-D28 -> 0
A29: Sr = STDEV(...) | B29: =STDEV(B18:C23) | C29: =STDEV(B18:C23) -> 0.01941161 | D29: 0.01941161 | E29: =C29-D29 -> 0
A30: RSDr = Sr/x̄ | B30: =STDEV(B18:C23)/AVERAGE(B18:C23) | C30: =STDEV(B18:C23)/AVERAGE(B18:C23) -> 0.040518233 | D30: 0.040518233 | E30: =C30-D30 -> 0
A31: r = 2.83·Sr | B31: =2.83*STDEV(B18:C23) | C31: =2.83*STDEV(B18:C23) -> 0.054934857 | D31: 0.054934857 | E31: =C31-D31 -> 0
A32: Pool katkısı = RSDr²·(n−1) | B32: =((STDEV(B18:C23)/AVERAGE(B18:C23))^2)*(COUNT(B18:C23)-1) | C32: =((STDEV(B18:C23)/AVERAGE(B18:C23))^2)*(COUNT(B18:C23)-1) -> 0.018058999 | D32: 0.018058999 | E32: =C32-D32 -> 0
A34: ── GRUBBS AYKIRI DEĞER TESTİ (Ali Berkan Akdoğan) (α=0.05) ──
A35: En uç değer (|x_i − x̄|max) | B35: =MAX(MAX(B18:C23)-AVERAGE(B18:C23),AVERAGE(B18:C23)-MIN(B18:C23)) | C35: =MAX(MAX(B18:C23)-AVERAGE(B18:C23),AVERAGE(B18:C23)-MIN(B18:C23)) -> 0.028916667 | D35: 0.028916667 | E35: =C35-D35 -> 0
A36: s = STDEV(...) | B36: =STDEV(B18:C23) | C36: =STDEV(B18:C23) -> 0.01941161 | D36: 0.01941161 | E36: =C36-D36 -> 0
A37: G_hesap = |x_i − x̄|max / s | B37: =MAX(MAX(B18:C23)-AVERAGE(B18:C23),AVERAGE(B18:C23)-MIN(B18:C23))/STDEV(B18:C23) | C37: =MAX(MAX(B18:C23)-AVERAGE(B18:C23),AVERAGE(B18:C23)-MIN(B18:C23))/STDEV(B18:C23) -> 1.4896583 | D37: 1.4896583 | E37: =C37-D37 -> 0
A38: n = COUNT(...) | B38: =COUNT(B18:C23) | C38: =COUNT(B18:C23) -> 12 | D38: 12 | E38: =C38-D38 -> 0
A39: G_kritik (α=0.05, tablo) | B39: =IFERROR(VLOOKUP(C38,'8. Grubbs Tablosu'!A2:B30,2,FALSE),2.745) | C39: =IFERROR(VLOOKUP(C38,'8. Grubbs Tablosu'!A2:B30,2,FALSE),2.745) -> 2.285 | D39: 2.285 | E39: =C39-D39 -> 0
A40: Karar: G_hesap > G_kritik ⇒ AYKIRI VAR | B40: =IF((MAX(MAX(B18:C23)-AVERAGE(B18:C23),AVERAGE(B18:C23)-MIN(B18:C23))/STDEV(B18:C23))>C39,"AYKIRI VAR (değeri inceleyin)","AYKIRI YOK (veri kabul)") | C40: =IF((MAX(MAX(B18:C23)-AVERAGE(B18:C23),AVERAGE(B18:C23)-MIN(B18:C23))/STDEV(B18:C23))>C39,"AYKIRI VAR (değeri inceleyin)","AYKIRI YOK (veri kabul)") -> AYKIRI YOK (veri kabul) | D40: AYKIRI YOK
A42: ── Efsu Nur Akyol ──
A43: n | B43: =COUNT(D18:E23) | C43: =COUNT(D18:E23) -> 12 | D43: 12 | E43: =C43-D43 -> 0
A44: x̄ | B44: =AVERAGE(D18:E23) | C44: =AVERAGE(D18:E23) -> 0.52258333 | D44: 0.52258333 | E44: =C44-D44 -> 0
A45: Sr | B45: =STDEV(D18:E23) | C45: =STDEV(D18:E23) -> 0.018337534 | D45: 0.018337534 | E45: =C45-D45 -> 0
A46: RSDr | B46: =STDEV(D18:E23)/AVERAGE(D18:E23) | C46: =STDEV(D18:E23)/AVERAGE(D18:E23) -> 0.035090162 | D46: 0.035090162 | E46: =C46-D46 -> 0
...

Sheet 5. Tekrarüretilebilirlik
A1: TEKRARÜRETİLEBİLİRLİK — POOLED RSD ve F-TESTİ
A3: TEORİK FORMÜLLER (Kaynak: PrecisionReproducibilityForm.tsx)
A4: Personel başına: x̄, Sr, RSDr (tekrarlanabilirlik ile aynı formüller).
A5: RSDpool = √[ Σ(RSDr² · (n−1)) / Σ(n−1) ]
A6: F-testi (kişiler arası varyans homojenliği):
A7: Fhesap = s²(max) / s²(min)
A8: Fkritik = F(α=0.05; df1=n_max−1; df2=n_min−1) (Excel: =F.INV.RT(0.05;df1;df2))
A9: Karar: Fhesap < Fkritik ⇒ UYGUN
A10: r = 2.83 · Sr
A12: KOMPONENT: Fumaric acid, bis-mehyl ester (DMFu) | Birim: mg_kg
A14: No | B14: Tarih | C14: Ali Berkan Akdoğan | D14: Efsu Nur Akyol
A15: 1 | B15: 2025-10-06 | C15: 0.448 | D15: 0.482
A16: 2 | B16: 2025-10-07 | C16: 0.493 | D16: 0.472
A17: 3 | B17: 2025-10-08 | C17: 0.457 | D17: 0.497
A18: 4 | B18: 2025-10-09 | C18: 0.489 | D18: 0.497
A19: 5 | B19: 2025-10-10 | C19: 0.446 | D19: 0.473
A20: 6 | B20: 2025-10-11 | C20: 0.443 | D20: 0.467
A22: Hesap | B22: Excel Formülü | C22: Hesap | D22: Sistem | E22: Fark
A23: ── Ali Berkan Akdoğan ──
A24: n | B24: =COUNT(C15:C20) | C24: =COUNT(C15:C20) -> 6 | D24: 6 | E24: =C24-D24 -> 0
A25: x̄ | B25: =AVERAGE(C15:C20) | C25: =AVERAGE(C15:C20) -> 0.46266667 | D25: 0.46266667 | E25: =C25-D25 -> 0
A26: Sr | B26: =STDEV(C15:C20) | C26: =STDEV(C15:C20) -> 0.022473688 | D26: 0.022473688 | E26: =C26-D26 -> 0
A27: Varyans s² = VAR(...) | B27: =VAR(C15:C20) | C27: =VAR(C15:C20) -> 0.00050506667 | D27: 0.00050506667 | E27: =C27-D27 -> 0
A28: RSDr | B28: =STDEV(C15:C20)/AVERAGE(C15:C20) | C28: =STDEV(C15:C20)/AVERAGE(C15:C20) -> 0.048574254 | D28: 0.048574254 | E28: =C28-D28 -> 0
A29: r = 2.83·Sr | B29: =2.83*STDEV(C15:C20) | C29: =2.83*STDEV(C15:C20) -> 0.063600538 | D29: 0.063600538 | E29: =C29-D29 -> 0
A30: Pool katkısı = RSDr²·(n−1) | B30: =((STDEV(C15:C20)/AVERAGE(C15:C20))^2)*(COUNT(C15:C20)-1) | C30: =((STDEV(C15:C20)/AVERAGE(C15:C20))^2)*(COUNT(C15:C20)-1) -> 0.011797291 | D30: 0.011797291 | E30: =C30-D30 -> 0
A32: ── GRUBBS AYKIRI DEĞER TESTİ (Ali Berkan Akdoğan) (α=0.05) ──
A33: En uç değer (|x_i − x̄|max) | B33: =MAX(MAX(C15:C20)-AVERAGE(C15:C20),AVERAGE(C15:C20)-MIN(C15:C20)) | C33: =MAX(MAX(C15:C20)-AVERAGE(C15:C20),AVERAGE(C15:C20)-MIN(C15:C20)) -> 0.030333333 | D33: 0.030333333 | E33: =C33-D33 -> 0
A34: s = STDEV(...) | B34: =STDEV(C15:C20) | C34: =STDEV(C15:C20) -> 0.022473688 | D34: 0.022473688 | E34: =C34-D34 -> 0
A35: G_hesap = |x_i − x̄|max / s | B35: =MAX(MAX(C15:C20)-AVERAGE(C15:C20),AVERAGE(C15:C20)-MIN(C15:C20))/STDEV(C15:C20) | C35: =MAX(MAX(C15:C20)-AVERAGE(C15:C20),AVERAGE(C15:C20)-MIN(C15:C20))/STDEV(C15:C20) -> 1.3497265 | D35: 1.3497265 | E35: =C35-D35 -> 0
A36: n = COUNT(...) | B36: =COUNT(C15:C20) | C36: =COUNT(C15:C20) -> 6 | D36: 6 | E36: =C36-D36 -> 0
A37: G_kritik (α=0.05, tablo) | B37: =IFERROR(VLOOKUP(C36,'8. Grubbs Tablosu'!A2:B30,2,FALSE),2.745) | C37: =IFERROR(VLOOKUP(C36,'8. Grubbs Tablosu'!A2:B30,2,FALSE),2.745) -> 1.822 | D37: 1.822 | E37: =C37-D37 -> 0
A38: Karar: G_hesap > G_kritik ⇒ AYKIRI VAR | B38: =IF((MAX(MAX(C15:C20)-AVERAGE(C15:C20),AVERAGE(C15:C20)-MIN(C15:C20))/STDEV(C15:C20))>C37,"AYKIRI VAR (değeri inceleyin)","AYKIRI YOK (veri kabul)") | C38: =IF((MAX(MAX(C15:C20)-AVERAGE(C15:C20),AVERAGE(C15:C20)-MIN(C15:C20))/STDEV(C15:C20))>C37,"AYKIRI VAR (değeri inceleyin)","AYKIRI YOK (veri kabul)") -> AYKIRI YOK (veri kabul) | D38: AYKIRI YOK
A40: ── Efsu Nur Akyol ──
A41: n | B41: =COUNT(D15:D20) | C41: =COUNT(D15:D20) -> 6 | D41: 6 | E41: =C41-D41 -> 0
A42: x̄ | B42: =AVERAGE(D15:D20) | C42: =AVERAGE(D15:D20) -> 0.48133333 | D42: 0.48133333 | E42: =C42-D42 -> 0
A43: Sr | B43: =STDEV(D15:D20) | C43: =STDEV(D15:D20) -> 0.013063945 | D43: 0.013063945 | E43: =C43-D43 -> 0
A44: Varyans s² = VAR(...) | B44: =VAR(D15:D20) | C44: =VAR(D15:D20) -> 0.00017066667 | D44: 0.00017066667 | E44: =C44-D44 -> 0
A45: RSDr | B45: =STDEV(D15:D20)/AVERAGE(D15:D20) | C45: =STDEV(D15:D20)/AVERAGE(D15:D20) -> 0.027141161 | D45: 0.027141161 | E45: =C45-D45 -> 0
A46: r = 2.83·Sr | B46: =2.83*STDEV(D15:D20) | C46: =2.83*STDEV(D15:D20) -> 0.036970965 | D46: 0.036970965 | E46: =C46-D46 -> 0
...

Sheet 6. Gerçeklik
A1: GERÇEKLİK (TRUENESS) — RECOVERY %, BIAS, U(BIAS), t-TESTİ
A3: TEORİK FORMÜLLER (Kaynak: TruenessStudyForm.tsx)
A4: Birim faktörü (ppm): mg/L,mg/kg=1; µg/L,µg/kg=0.001; ng/L=1e-6; %=10000
A5: Recovery_i = (x_i · faktör) / (hedef · faktör) · 100
A6: Personel başına: x̄, Sr (STDEV), RSD = Sr/x̄
A7: Havuz (tüm personel — recovery oranlarından):
A8: R̄ = Σ(recovery_i/100) / n
A9: s_R = √[ Σ(R_i − R̄)² / (n−1) ]
A10: U(x) = s_R / √n
A11: Bias % = (1 − R̄) · 100
A12: U(Bias) = √[ ((1 − R̄)/√3)² + U(x)² ]
A13: t_hesap = |1 − R̄| / U(x)
... A17: KOMPONENT: Fumaric acid, bis-mehyl ester (DMFu) | Birim: mg_kg | Hedef: 1
A19: No | B19: Ali Berkan Akdoğan | C19: Efsu Nur Akyol | D19: Recovery % (P1) | E19: Recovery % (P2)
A20: 1 | B20: 1.029 | C20: 0.968 | D20: =B20/1*100 | E20: =C20/1*100
A21: 2 | B21: 1.044 | C21: 1.067 | D21: =B21/1*100 | E21: =C21/1*100
A22: 3 | B22: 1.028 | C22: 1.095 | D22: =B22/1*100 | E22: =C22/1*100
A23: 4 | B23: 0.961 | C23: 1.022 | D23: =B23/1*100 | E23: =C23/1*100
A24: 5 | B24: 1.027 | C24: 1.057 | D24: =B24/1*100 | E24: =C24/1*100
A25: 6 | B25: 0.985 | C25: 1.054 | D25: =B25/1*100 | E25: =C25/1*100
A26: 7 | B26: 1.004 | C26: 1.053 | D26: =B26/1*100 | E26: =C26/1*100
A27: 8 | B27: 1.058 | C27: 0.953 | D27: =B27/1*100 | E27: =C27/1*100
A28: 9 | B28: 0.965 | C28: 1.051 | D28: =B28/1*100 | E28: =C28/1*100
A29: 10 | B29: 1.022 | C29: 1.029 | D29: =B29/1*100 | E29: =C29/1*100
A30: 11 | B30: 0.971 | C30: 1.079 | D30: =B30/1*100 | E30: =C30/1*100
A31: 12 | B31: 1.013 | C31: 0.975 | D31: =B31/1*100 | E31: =C31/1*100
A33: Hesap | B33: Excel Formülü | C33: Hesap | D33: Sistem | E33: Fark
A34: ── Ali Berkan Akdoğan ──
A35: n | B35: =COUNT(B20:B31) | C35: =COUNT(B20:B31) -> 12 | D35: 12 | E35: =C35-D35 -> 0
A36: x̄ | B36: =AVERAGE(B20:B31) | C36: =AVERAGE(B20:B31) -> 1.0089167 | D36: 1.0089167 | E36: =C36-D36 -> 0
A37: Sr | B37: =STDEV(B20:B31) | C37: =STDEV(B20:B31) -> 0.031881765 | D37: 0.031881765 | E37: =C37-D37 -> 0
A38: RSD = Sr/x̄ | B38: =STDEV(B20:B31)/AVERAGE(B20:B31) | C38: =STDEV(B20:B31)/AVERAGE(B20:B31) -> 0.031599999 | D38: 0.031599999 | E38: =C38-D38 -> 0
A40: ── Efsu Nur Akyol ──
A41: n | B41: =COUNT(C20:C31) | C41: =COUNT(C20:C31) -> 12 | D41: 12 | E41: =C41-D41 -> 0
A42: x̄ | B42: =AVERAGE(C20:C31) | C42: =AVERAGE(C20:C31) -> 1.0335833 | D42: 1.0335833 | E42: =C42-D42 -> 0
A43: Sr | B43: =STDEV(C20:C31) | C43: =STDEV(C20:C31) -> 0.045705497 | D43: 0.045705497 | E43: =C43-D43 -> 0
A44: RSD | B44: =STDEV(C20:C31)/AVERAGE(C20:C31) | C44: =STDEV(C20:C31)/AVERAGE(C20:C31) -> 0.044220427 | D44: 0.044220427 | E44: =C44-D44 -> 0
A46: ── HAVUZ (tüm personel — recovery oranlarından) ──
A47: R̄ (mean, 0-1) = AVERAGE(Rec%)/100 | B47: =AVERAGE(D20:E31)/100 | C47: =AVERAGE(D20:E31)/100 -> 1.02125 | D47: 1.02125 | E47: =C47-D47 -> 0
A48: R̄ % | B48: =AVERAGE(D20:E31) | C48: =AVERAGE(D20:E31) -> 102.125 | D48: 102.125 | E48: =C48-D48 -> 0
...

Sheet 7. Belirsizlik
A1: ÖLÇÜM BELİRSİZLİĞİ (GUM / ISO/IEC Guide 98-3)
A3: TEORİK FORMÜLLER (Kaynak: MeasurementUncertaintyBudgetForm.tsx + SamplePreparationUncertaintyForm.tsx)
A4: 1) Bileşen standart belirsizliği: u_x = U / k (k=2 normal/Gauss; k=√3≈1.732 dikdörtgen; k=√6≈2.449 üçgensel)
A5: 2) Relatif: u_rel = u_x / x
A6: 3) Hacimsel cam sıcaklık belirsizliği: u_T = (2.1·10⁻⁴ · 5 · V) / √3 (V=mL, ΔT=5°C lab aralığı)
A7: 4) Birleşik (RSS): u_c = √( u_lin² + u_repeat² + u_repro² + u_bias² + u_prep_devices² + u_prep_chemicals² )
A8: 5) Genişletilmiş: U = k · u_c (k=2 ⇒ %95 güven aralığı)
A9: 6) Bileşen katkı yüzdesi: (u_i² / Σu_i²) · 100
A11: VALIDASYON 21 — BÜTÇE (komponent: Fumaric acid, bis-mehyl ester (DMFu))
A12: NOT: Bileşen değerleri ilgili modüllerde hesaplanmıştır. Burada RSS (kareler toplamının karekökü) ile birleştirilmektedir.
A14: Bileşen Kaynağı | B14: Açıklama | C14: u_i (relatif) | D14: u_i² (kareli) | E14: % Katkı
A15: u_linearity (Doğrusallık U(Co)) | B15: LINEARITY modülünden: (s/b1)·√(1/p+1/(n·p)+(Co−x̄)²/Sxx) | C15: 0.0070476629 | D15: =C15^2
A16: u_repeatability (en yüksek RSDpool) | B16: REPEATABILITY: max(RSDpool, düzeyler — worst-case) | C16: 0.037901495 | D16: =C16^2
A17: u_reproducibility (RSDpool) | B17: REPRODUCIBILITY: havuzlanmış RSD | C17: 0.039345271 | D17: =C17^2
A18: u_bias (Gerçeklik U(Bias)) | B18: TRUENESS: √[((1−R̄)/√3)² + U(x)²] | C18: 0.014799261 | D18: =C18^2
A19: u_prep_devices | B19: Numune Hazırlama — pipet/balon/terazi RSS | C19: 0 | D19: =C19^2
A20: u_prep_chemicals | B20: Numune Hazırlama — standart kimyasal RSS | C20: 0 | D20: =C20^2
A21: Σu_i² (toplam varyans) | D21: =SUM(D15:D20)
A22: u_c = √(Σu_i²) | B22: =SQRT(D21) | C22: =SQRT(D21)
A23: k (kapsam faktörü, %95) | C23: 2
A24: U = k · u_c (genişletilmiş belirsizlik) | B24: =C23*C22 | C24: =C23*C22
A26: BİLEŞEN KATKI YÜZDELERİ (Pareto)
A27: u_linearity (Doğrusallık U(Co)) | E27: =D15/D21*100
A28: u_repeatability (en yüksek RSDpool) | E28: =D16/D21*100
A29: u_reproducibility (RSDpool) | E29: =D17/D21*100
A30: u_bias (Gerçeklik U(Bias)) | E30: =D18/D21*100
A31: u_prep_devices | E31: =D19/D21*100
A32: u_prep_chemicals | E32: =D20/D21*100
A34: NOT: Validasyon 21'de Numune Hazırlama modülü boştur, u_prep_devices ve u_prep_chemicals = 0 alınmıştır. Eklendiğinde RSS otomatik yeniden hesaplanacaktır.

Sheet 8. Grubbs Tablosu
A1: n | B1: G_kritik (α=0.05) | D1: GRUBBS AYKIRI DEĞER TESTİ — KRİTİK DEĞER TABLOSU
A2: 3 | B2: 1.153 | D2: KAYNAK: ISO 5725-2 ve Grubbs (1969) "Procedures for Detecting Outlying Observations".
A3: 4 | B3: 1.463 | D3: Eurachem Guide "The Fitness for Purpose of Analytical Methods" (2nd ed., 2014)
A4: 5 | B4: 1.672 | D4: aykırı değer testleri arasında Grubbs testini önerir.
A5: 6 | B5: 1.822
A6: 7 | B6: 1.938 | D6: TEST İLKESİ:
A7: 8 | B7: 2.032 | D7: G_hesap = |x_uç − x̄| / s
A8: 9 | B8: 2.11 | D8: Burada x_uç, ortalamadan en uzak değer (max veya min).
A9: 10 | B9: 2.176
A10: 11 | B10: 2.234 | D10: KARAR:
A11: 12 | B11: 2.285 | D11: G_hesap > G_kritik(n, α=0.05) ⇒ değer aykırı (outlier).
A12: 13 | B12: 2.331 | D12: G_hesap ≤ G_kritik ⇒ veri normal dağılıma uygun, dışlanmaz.
A13: 14 | B13: 2.371
A14: 15 | B14: 2.409 | D14: n > 30 için sistemde 2.745 kullanılır (tablodan ekstrapolasyon).
A15: 16 | B15: 2.443
A16: 17 | B16: 2.475 | D16: KAYNAK KODU: components/validation/shared/grubbs.ts — calculateGrubbs()
A17: 18 | B17: 2.504
A18: 19 | B18: 2.532
A19: 20 | B19: 2.557
A20: 21 | B20: 2.58
A21: 22 | B21: 2.603
A22: 23 | B22: 2.624
A23: 24 | B23: 2.644
A24: 25 | B24: 2.663
A25: 26 | B25: 2.681
A26: 27 | B26: 2.698
A27: 28 | B27: 2.714
A28: 29 | B28: 2.73
A29: 30 | B29: 2.745

Sheet 9. Eurachem Uygunluk
A1: EURACHEM REHBER UYGUNLUK DEĞERLENDİRMESİ
A3: REFERANS REHBERLER
A4: EURACHEM-FFP-2014 | B4: Eurachem Guide "The Fitness for Purpose of Analytical Methods — A Laboratory Guide to Method Validation and Related Topics", 2nd Edition, 2014, ISBN 978-91-87461-59-0
A5: EURACHEM-CG4-2012 | B5: Eurachem/CITAC Guide CG 4 "Quantifying Uncertainty in Analytical Measurement", 3rd Edition, 2012
A6: ISO 5725-2:2019 | B6: Accuracy (trueness and precision) of measurement methods and results — Part 2: Basic methods
A7: ISO/IEC Guide 98-3 (GUM) | B7: Uncertainty of measurement — Part 3: Guide to the expression of uncertainty in measurement (2008)
A8: IUPAC / ICH Q2(R1) | B8: Validation of Analytical Procedures: Text and Methodology
A9: AOAC PVMP | B9: AOAC Manual for the Peer Verified Methods Program — Analyte Recovery Table
A11: DEĞERLENDİRME TABLOSU
A12: Hesaplama / Parametre | B12: Sistemdeki Formül | C12: Eurachem / İlgili Rehber Referansı | D12: Uyum | E12: Açıklama
A13: LOD = μ + 3·σ | B13: Düşük seviye spike numunelerden (Bessel: n−1) | C13: Eurachem FFP §8.3.2: spike (low-conc) yöntemi ile μ + 3·σ; IUPAC/ICH Q2(R1) §6.3.2 | D13: UYGUN | E13: Eurachem 3 farklı yaklaşımı kabul eder: (1) S/N=3, (2) blank + 3·σ_blank, (3) düşük seviye spike. Sistem (3) yaklaşımını uyguluyor — Eurachem tarafından kabul gören standart yöntemdir.
A14: LOQ = μ + 10·σ | B14: Düşük seviye spike numunelerden | C14: Eurachem FFP §8.3.3; IUPAC/ICH Q2(R1) | D14: UYGUN | E14: LOQ için 10·σ kullanımı IUPAC ve Eurachem ile birebir uyumlu. ICH Q2(R1) da bu formülü açıkça önerir.
A15: Slope, Intercept (OLS regresyon) | B15: En küçük kareler: SLOPE / INTERCEPT formülleri | C15: Eurachem FFP §6.4 ve Ek B; ISO 11095 | D15: UYGUN | E15: Standart en küçük kareler regresyonu. Eurachem ağırlıklı regresyon (WLS) da önerir; sistemde homoscedastik (eşit varyans) varsayımı kullanılıyor.
A16: R² (Belirleme Katsayısı) | B16: r² (Pearson korelasyonunun karesi) | C16: Eurachem FFP §6.4: korelasyon yalnız uygunluk göstergesidir, tek başına yeterli değildir | D16: UYGUN — UYARI | E16: Eurachem R²'yi kabul kriteri olarak yeterli görmez, residual analizi de önerir. Sistem rezidüel hesaplar (Y−ŷ ve karesi) — Eurachem ile UYGUN.
A17: U(Co) — kalibrasyon belirsizliği | B17: (s/b1)·√(1/p + 1/(n·p) + (Co−x̄)²/Sxx) | C17: Eurachem CG-4 §A.2.4 (Linear calibration) | D17: UYGUN | E17: Eurachem CG-4 Ek A.2.4'teki kalibrasyon belirsizliği formülünün birebir karşılığı. p = okutma sayısı (sistem p=3 sabiti, lab konvansiyonu).
A18: Sr (Repeatability StDev) | B18: √[ Σ(xi − x̄)² / (n−1) ] (Bessel) | C18: ISO 5725-2 §7; Eurachem FFP §6.5.1 | D18: UYGUN | E18: ISO 5725-2 standart tanımı. Eurachem tüm precision hesaplarında bu formülü kullanır.
A19: RSDr = Sr / x̄ | B19: Relatif standart sapma | C19: Eurachem FFP §6.5.1 (yorumlama Horwitz oranı ile) | D19: UYGUN | E19: Eurachem hem Horwitz oranı hem RSDr/RSDR kullanımını kabul eder.
A20: r = 2.83 · Sr | B20: Tekrarlanabilirlik limiti | C20: ISO 5725-6 §4.1.1 (r = 2√2·Sr ≈ 2.83·Sr, %95) | D20: UYGUN | E20: ISO 5725-6'nın resmi tanımı. Eurachem FFP §6.5.1 bu limiti aynen kullanır.
A21: Havuzlanmış RSD (RSDpool) | B21: √[ Σ(RSDr²·(n−1)) / Σ(n−1) ] | C21: Eurachem FFP §6.5.2 ve Nordtest TR 537 §5 | D21: UYGUN | E21: Pooled SD/RSD yaygın standart formül. Eurachem birden çok düzey / personel verilerinin birleştirilmesinde önerir.
A22: F-testi (varyans homojenliği) | B22: F = s²max / s²min; F_kritik = F.INV.RT(α=0.05; df1; df2) | C22: Eurachem FFP §6.5.3; ISO 5725-2 §7.3.3 | D22: UYGUN | E22: İki veya daha fazla operatörün varyanslarının kıyaslanması için Eurachem'in standart önerisi.
A23: Recovery % = (ölçülen/hedef)·100 | B23: Spike/CRM ile geri kazanım | C23: Eurachem FFP §6.6.1; AOAC PVMP | D23: UYGUN | E23: Eurachem ve AOAC bu formülü standart kullanır.
... A33: Bileşen katkı yüzdesi | B33: (u_i² / Σu_i²) · 100 | C33: Eurachem CG-4 §8.2 (uncertainty budget pie chart) | D33: UYGUN | E33: Belirsizlik bütçesi Pareto görselleştirmesi için Eurachem'in standart önerisi.
A36: GENEL DEĞERLENDİRME
A37: Validasyon 21 (DMFu Tayini) ekranında kullanılan TÜM hesaplama algoritmaları, Eurachem
A38: Guide "The Fitness for Purpose of Analytical Methods" (2014) ve Eurachem/CITAC CG 4 (2012)
A39: rehberlerinde tanımlı standart formüllerle BİREBİR UYUMLUDUR.
A41: Spesifik olarak doğrulanan ana başlıklar:
A42: • Doğrusallık — OLS regresyon (Eurachem FFP §6.4 ile uygun)
A43: • LOD/LOQ — düşük seviye spike yaklaşımı (Eurachem FFP §8.3, IUPAC, ICH Q2)
A44: • Tekrarlanabilirlik / Tekrarüretilebilirlik — ISO 5725-2 ve Eurachem §6.5
A45: • Gerçeklik (Trueness) — Recovery + Bias belirsizliği (Eurachem CG-4 §7.16)
A46: • Ölçüm Belirsizliği — GUM/Eurachem CG-4 tam uyumlu RSS yaklaşımı
A47: • Aykırı Değer Testi — Grubbs (Eurachem FFP §8 önerisi)
A49: BİR DİKKAT NOKTASI:
... A54: AKREDİTASYON SUNUMU İÇİN UYGUNDUR.
